[2023-12-12T23:05:50.797+0000] {taskinstance.py:1159} INFO - Dependencies all met for dep_context=non-requeueable deps ti=<TaskInstance: currency_exchange.fetch_exchange_rates scheduled__2023-12-07T10:00:00+00:00 [queued]>
[2023-12-12T23:05:51.212+0000] {taskinstance.py:1159} INFO - Dependencies all met for dep_context=requeueable deps ti=<TaskInstance: currency_exchange.fetch_exchange_rates scheduled__2023-12-07T10:00:00+00:00 [queued]>
[2023-12-12T23:05:51.222+0000] {taskinstance.py:1361} INFO - Starting attempt 1 of 4
[2023-12-12T23:05:52.893+0000] {taskinstance.py:1382} INFO - Executing <Task(PythonOperator): fetch_exchange_rates> on 2023-12-07 10:00:00+00:00
[2023-12-12T23:05:53.870+0000] {standard_task_runner.py:57} INFO - Started process 20783 to run task
[2023-12-12T23:05:54.027+0000] {standard_task_runner.py:84} INFO - Running: ['***', 'tasks', 'run', 'currency_exchange', 'fetch_exchange_rates', 'scheduled__2023-12-07T10:00:00+00:00', '--job-id', '355', '--raw', '--subdir', 'DAGS_FOLDER/currency_exchange_dag.py', '--cfg-path', '/tmp/tmpgf8w7mcl']
[2023-12-12T23:05:54.327+0000] {standard_task_runner.py:85} INFO - Job 355: Subtask fetch_exchange_rates
[2023-12-12T23:05:55.756+0000] {task_command.py:416} INFO - Running <TaskInstance: currency_exchange.fetch_exchange_rates scheduled__2023-12-07T10:00:00+00:00 [running]> on host d5f251ea7e03
[2023-12-12T23:05:56.428+0000] {taskinstance.py:1662} INFO - Exporting env vars: AIRFLOW_CTX_DAG_OWNER='currency' AIRFLOW_CTX_DAG_ID='currency_exchange' AIRFLOW_CTX_TASK_ID='fetch_exchange_rates' AIRFLOW_CTX_EXECUTION_DATE='2023-12-07T10:00:00+00:00' AIRFLOW_CTX_TRY_NUMBER='1' AIRFLOW_CTX_DAG_RUN_ID='scheduled__2023-12-07T10:00:00+00:00'
[2023-12-12T23:05:59.472+0000] {taskinstance.py:1937} ERROR - Task failed with exception
Traceback (most recent call last):
  File "/home/airflow/.local/lib/python3.8/site-packages/urllib3/connection.py", line 174, in _new_conn
    conn = connection.create_connection(
  File "/home/airflow/.local/lib/python3.8/site-packages/urllib3/util/connection.py", line 95, in create_connection
    raise err
  File "/home/airflow/.local/lib/python3.8/site-packages/urllib3/util/connection.py", line 85, in create_connection
    sock.connect(sa)
ConnectionResetError: [Errno 104] Connection reset by peer

During handling of the above exception, another exception occurred:

Traceback (most recent call last):
  File "/home/airflow/.local/lib/python3.8/site-packages/urllib3/connectionpool.py", line 715, in urlopen
    httplib_response = self._make_request(
  File "/home/airflow/.local/lib/python3.8/site-packages/urllib3/connectionpool.py", line 404, in _make_request
    self._validate_conn(conn)
  File "/home/airflow/.local/lib/python3.8/site-packages/urllib3/connectionpool.py", line 1058, in _validate_conn
    conn.connect()
  File "/home/airflow/.local/lib/python3.8/site-packages/urllib3/connection.py", line 363, in connect
    self.sock = conn = self._new_conn()
  File "/home/airflow/.local/lib/python3.8/site-packages/urllib3/connection.py", line 186, in _new_conn
    raise NewConnectionError(
urllib3.exceptions.NewConnectionError: <urllib3.connection.HTTPSConnection object at 0xffff78a55f40>: Failed to establish a new connection: [Errno 104] Connection reset by peer

During handling of the above exception, another exception occurred:

Traceback (most recent call last):
  File "/home/airflow/.local/lib/python3.8/site-packages/requests/adapters.py", line 486, in send
    resp = conn.urlopen(
  File "/home/airflow/.local/lib/python3.8/site-packages/urllib3/connectionpool.py", line 799, in urlopen
    retries = retries.increment(
  File "/home/airflow/.local/lib/python3.8/site-packages/urllib3/util/retry.py", line 592, in increment
    raise MaxRetryError(_pool, url, error or ResponseError(cause))
urllib3.exceptions.MaxRetryError: HTTPSConnectionPool(host='cdn.jsdelivr.net', port=443): Max retries exceeded with url: /gh/fawazahmed0/currency-api@1/2023-12-12/currencies/usd/eur.json (Caused by NewConnectionError('<urllib3.connection.HTTPSConnection object at 0xffff78a55f40>: Failed to establish a new connection: [Errno 104] Connection reset by peer'))

During handling of the above exception, another exception occurred:

Traceback (most recent call last):
  File "/home/airflow/.local/lib/python3.8/site-packages/airflow/operators/python.py", line 192, in execute
    return_value = self.execute_callable()
  File "/home/airflow/.local/lib/python3.8/site-packages/airflow/operators/python.py", line 209, in execute_callable
    return self.python_callable(*self.op_args, **self.op_kwargs)
  File "/opt/airflow/dags/currency_exchange_dag.py", line 39, in fetch_exchange_rates_task
    exchange_rates_data = get_currency_exchange(base_currency, curr_list, date)
  File "/opt/airflow/dags/currency_exchange_dag.py", line 26, in get_currency_exchange
    response = requests.get(api)
  File "/home/airflow/.local/lib/python3.8/site-packages/requests/api.py", line 73, in get
    return request("get", url, params=params, **kwargs)
  File "/home/airflow/.local/lib/python3.8/site-packages/requests/api.py", line 59, in request
    return session.request(method=method, url=url, **kwargs)
  File "/home/airflow/.local/lib/python3.8/site-packages/requests/sessions.py", line 589, in request
    resp = self.send(prep, **send_kwargs)
  File "/home/airflow/.local/lib/python3.8/site-packages/requests/sessions.py", line 703, in send
    r = adapter.send(request, **kwargs)
  File "/home/airflow/.local/lib/python3.8/site-packages/requests/adapters.py", line 519, in send
    raise ConnectionError(e, request=request)
requests.exceptions.ConnectionError: HTTPSConnectionPool(host='cdn.jsdelivr.net', port=443): Max retries exceeded with url: /gh/fawazahmed0/currency-api@1/2023-12-12/currencies/usd/eur.json (Caused by NewConnectionError('<urllib3.connection.HTTPSConnection object at 0xffff78a55f40>: Failed to establish a new connection: [Errno 104] Connection reset by peer'))
[2023-12-12T23:06:01.650+0000] {taskinstance.py:1400} INFO - Marking task as UP_FOR_RETRY. dag_id=currency_exchange, task_id=fetch_exchange_rates, execution_date=20231207T100000, start_date=20231212T230550, end_date=20231212T230601
[2023-12-12T23:06:02.092+0000] {standard_task_runner.py:104} ERROR - Failed to execute job 355 for task fetch_exchange_rates (HTTPSConnectionPool(host='cdn.jsdelivr.net', port=443): Max retries exceeded with url: /gh/fawazahmed0/currency-api@1/2023-12-12/currencies/usd/eur.json (Caused by NewConnectionError('<urllib3.connection.HTTPSConnection object at 0xffff78a55f40>: Failed to establish a new connection: [Errno 104] Connection reset by peer')); 20783)
[2023-12-12T23:06:02.923+0000] {local_task_job_runner.py:228} INFO - Task exited with return code 1
[2023-12-12T23:06:03.501+0000] {taskinstance.py:2778} INFO - 0 downstream tasks scheduled from follow-on schedule check
