[2023-12-11T22:36:59.736+0000] {taskinstance.py:1159} INFO - Dependencies all met for dep_context=non-requeueable deps ti=<TaskInstance: postgres_dag_v02.insert_into_postgres_table scheduled__2023-12-01T05:00:00+00:00 [queued]>
[2023-12-11T22:37:01.003+0000] {taskinstance.py:1159} INFO - Dependencies all met for dep_context=requeueable deps ti=<TaskInstance: postgres_dag_v02.insert_into_postgres_table scheduled__2023-12-01T05:00:00+00:00 [queued]>
[2023-12-11T22:37:01.045+0000] {taskinstance.py:1361} INFO - Starting attempt 1 of 4
[2023-12-11T22:37:03.610+0000] {taskinstance.py:1382} INFO - Executing <Task(PostgresOperator): insert_into_postgres_table> on 2023-12-01 05:00:00+00:00
[2023-12-11T22:37:04.197+0000] {standard_task_runner.py:57} INFO - Started process 10526 to run task
[2023-12-11T22:37:04.854+0000] {standard_task_runner.py:84} INFO - Running: ['***', 'tasks', 'run', 'postgres_dag_v02', 'insert_into_postgres_table', 'scheduled__2023-12-01T05:00:00+00:00', '--job-id', '284', '--raw', '--subdir', 'DAGS_FOLDER/postgres_dag.py', '--cfg-path', '/tmp/tmp7huwu929']
[2023-12-11T22:37:05.217+0000] {standard_task_runner.py:85} INFO - Job 284: Subtask insert_into_postgres_table
[2023-12-11T22:37:12.323+0000] {task_command.py:416} INFO - Running <TaskInstance: postgres_dag_v02.insert_into_postgres_table scheduled__2023-12-01T05:00:00+00:00 [running]> on host d5f251ea7e03
[2023-12-11T22:37:14.920+0000] {taskinstance.py:1662} INFO - Exporting env vars: AIRFLOW_CTX_DAG_OWNER='sajal' AIRFLOW_CTX_DAG_ID='postgres_dag_v02' AIRFLOW_CTX_TASK_ID='insert_into_postgres_table' AIRFLOW_CTX_EXECUTION_DATE='2023-12-01T05:00:00+00:00' AIRFLOW_CTX_TRY_NUMBER='1' AIRFLOW_CTX_DAG_RUN_ID='scheduled__2023-12-01T05:00:00+00:00'
[2023-12-11T22:37:15.040+0000] {sql.py:274} INFO - Executing: 
        insert into dag_runs(dt, dag_id) values ( '2023-12-01', 'postgres_dag_v02')
    
[2023-12-11T22:37:15.221+0000] {base.py:73} INFO - Using connection ID 'postgres_localhost' for task execution.
[2023-12-11T22:37:15.754+0000] {base.py:73} INFO - Using connection ID 'postgres_localhost' for task execution.
[2023-12-11T22:37:16.172+0000] {sql.py:418} INFO - Running statement: 
        insert into dag_runs(dt, dag_id) values ( '2023-12-01', 'postgres_dag_v02')
    , parameters: None
[2023-12-11T22:37:16.236+0000] {taskinstance.py:1937} ERROR - Task failed with exception
Traceback (most recent call last):
  File "/home/airflow/.local/lib/python3.8/site-packages/airflow/providers/common/sql/operators/sql.py", line 280, in execute
    output = hook.run(
  File "/home/airflow/.local/lib/python3.8/site-packages/airflow/providers/common/sql/hooks/sql.py", line 392, in run
    self._run_command(cur, sql_statement, parameters)
  File "/home/airflow/.local/lib/python3.8/site-packages/airflow/providers/common/sql/hooks/sql.py", line 423, in _run_command
    cur.execute(sql_statement)
psycopg2.errors.UniqueViolation: duplicate key value violates unique constraint "dag_runs_pkey"
DETAIL:  Key (dt, dag_id)=(2023-12-01, postgres_dag_v02) already exists.

[2023-12-11T22:37:16.771+0000] {taskinstance.py:1400} INFO - Marking task as UP_FOR_RETRY. dag_id=postgres_dag_v02, task_id=insert_into_postgres_table, execution_date=20231201T050000, start_date=20231211T223700, end_date=20231211T223716
[2023-12-11T22:37:17.132+0000] {standard_task_runner.py:104} ERROR - Failed to execute job 284 for task insert_into_postgres_table (duplicate key value violates unique constraint "dag_runs_pkey"
DETAIL:  Key (dt, dag_id)=(2023-12-01, postgres_dag_v02) already exists.
; 10526)
[2023-12-11T22:37:23.054+0000] {local_task_job_runner.py:228} INFO - Task exited with return code 1
[2023-12-11T22:37:26.740+0000] {taskinstance.py:2778} INFO - 0 downstream tasks scheduled from follow-on schedule check
